{
 "cells": [
  {
   "cell_type": "code",
   "execution_count": 13,
   "id": "03fe8518",
   "metadata": {},
   "outputs": [
    {
     "name": "stdout",
     "output_type": "stream",
     "text": [
      "Requirement already satisfied: mysql-connector-python in ./miniconda3/envs/jupyter-env/lib/python3.11/site-packages (8.4.0)\n",
      "Note: you may need to restart the kernel to use updated packages.\n"
     ]
    }
   ],
   "source": [
    "pip install mysql-connector-python"
   ]
  },
  {
   "cell_type": "code",
   "execution_count": 14,
   "id": "f2afca21",
   "metadata": {},
   "outputs": [],
   "source": [
    "import mysql.connector"
   ]
  },
  {
   "cell_type": "code",
   "execution_count": 15,
   "id": "88606fbc",
   "metadata": {},
   "outputs": [
    {
     "ename": "InterfaceError",
     "evalue": "2003: Can't connect to MySQL server on 'localhost:3306' (61 Connection refused)",
     "output_type": "error",
     "traceback": [
      "\u001b[0;31m---------------------------------------------------------------------------\u001b[0m",
      "\u001b[0;31mConnectionRefusedError\u001b[0m                    Traceback (most recent call last)",
      "File \u001b[0;32m~/miniconda3/envs/jupyter-env/lib/python3.11/site-packages/mysql/connector/network.py:758\u001b[0m, in \u001b[0;36mMySQLTCPSocket.open_connection\u001b[0;34m(self)\u001b[0m\n\u001b[1;32m    757\u001b[0m     \u001b[38;5;28mself\u001b[39m\u001b[38;5;241m.\u001b[39msock\u001b[38;5;241m.\u001b[39msettimeout(\u001b[38;5;28mself\u001b[39m\u001b[38;5;241m.\u001b[39m_connection_timeout)\n\u001b[0;32m--> 758\u001b[0m     \u001b[38;5;28mself\u001b[39m\u001b[38;5;241m.\u001b[39msock\u001b[38;5;241m.\u001b[39mconnect(sockaddr)\n\u001b[1;32m    759\u001b[0m \u001b[38;5;28;01mexcept\u001b[39;00m \u001b[38;5;167;01mIOError\u001b[39;00m \u001b[38;5;28;01mas\u001b[39;00m err:\n",
      "\u001b[0;31mConnectionRefusedError\u001b[0m: [Errno 61] Connection refused",
      "\nThe above exception was the direct cause of the following exception:\n",
      "\u001b[0;31mInterfaceError\u001b[0m                            Traceback (most recent call last)",
      "Cell \u001b[0;32mIn[15], line 1\u001b[0m\n\u001b[0;32m----> 1\u001b[0m mydb \u001b[38;5;241m=\u001b[39m mysql\u001b[38;5;241m.\u001b[39mconnector\u001b[38;5;241m.\u001b[39mconnect(\n\u001b[1;32m      2\u001b[0m     host\u001b[38;5;241m=\u001b[39m\u001b[38;5;124m\"\u001b[39m\u001b[38;5;124mlocalhost\u001b[39m\u001b[38;5;124m\"\u001b[39m,\n\u001b[1;32m      3\u001b[0m     user\u001b[38;5;241m=\u001b[39m\u001b[38;5;124m\"\u001b[39m\u001b[38;5;124myourusername\u001b[39m\u001b[38;5;124m\"\u001b[39m,\n\u001b[1;32m      4\u001b[0m     password\u001b[38;5;241m=\u001b[39m\u001b[38;5;124m\"\u001b[39m\u001b[38;5;124myourpassword\u001b[39m\u001b[38;5;124m\"\u001b[39m,\n\u001b[1;32m      5\u001b[0m     database\u001b[38;5;241m=\u001b[39m\u001b[38;5;124m\"\u001b[39m\u001b[38;5;124myour_database\u001b[39m\u001b[38;5;124m\"\u001b[39m\n\u001b[1;32m      6\u001b[0m )\n\u001b[1;32m      9\u001b[0m cursor \u001b[38;5;241m=\u001b[39m mydb\u001b[38;5;241m.\u001b[39mcursor()\n",
      "File \u001b[0;32m~/miniconda3/envs/jupyter-env/lib/python3.11/site-packages/mysql/connector/pooling.py:323\u001b[0m, in \u001b[0;36mconnect\u001b[0;34m(*args, **kwargs)\u001b[0m\n\u001b[1;32m    321\u001b[0m \u001b[38;5;28;01mif\u001b[39;00m CMySQLConnection \u001b[38;5;129;01mand\u001b[39;00m \u001b[38;5;129;01mnot\u001b[39;00m use_pure:\n\u001b[1;32m    322\u001b[0m     \u001b[38;5;28;01mreturn\u001b[39;00m CMySQLConnection(\u001b[38;5;241m*\u001b[39margs, \u001b[38;5;241m*\u001b[39m\u001b[38;5;241m*\u001b[39mkwargs)\n\u001b[0;32m--> 323\u001b[0m \u001b[38;5;28;01mreturn\u001b[39;00m MySQLConnection(\u001b[38;5;241m*\u001b[39margs, \u001b[38;5;241m*\u001b[39m\u001b[38;5;241m*\u001b[39mkwargs)\n",
      "File \u001b[0;32m~/miniconda3/envs/jupyter-env/lib/python3.11/site-packages/mysql/connector/connection.py:180\u001b[0m, in \u001b[0;36mMySQLConnection.__init__\u001b[0;34m(self, **kwargs)\u001b[0m\n\u001b[1;32m    178\u001b[0m \u001b[38;5;28;01mif\u001b[39;00m kwargs:\n\u001b[1;32m    179\u001b[0m     \u001b[38;5;28;01mtry\u001b[39;00m:\n\u001b[0;32m--> 180\u001b[0m         \u001b[38;5;28mself\u001b[39m\u001b[38;5;241m.\u001b[39mconnect(\u001b[38;5;241m*\u001b[39m\u001b[38;5;241m*\u001b[39mkwargs)\n\u001b[1;32m    181\u001b[0m     \u001b[38;5;28;01mexcept\u001b[39;00m \u001b[38;5;167;01mException\u001b[39;00m:\n\u001b[1;32m    182\u001b[0m         \u001b[38;5;66;03m# Tidy-up underlying socket on failure\u001b[39;00m\n\u001b[1;32m    183\u001b[0m         \u001b[38;5;28mself\u001b[39m\u001b[38;5;241m.\u001b[39mclose()\n",
      "File \u001b[0;32m~/miniconda3/envs/jupyter-env/lib/python3.11/site-packages/mysql/connector/abstracts.py:1360\u001b[0m, in \u001b[0;36mMySQLConnectionAbstract.connect\u001b[0;34m(self, **kwargs)\u001b[0m\n\u001b[1;32m   1357\u001b[0m     \u001b[38;5;28mself\u001b[39m\u001b[38;5;241m.\u001b[39mconfig(\u001b[38;5;241m*\u001b[39m\u001b[38;5;241m*\u001b[39mkwargs)\n\u001b[1;32m   1359\u001b[0m \u001b[38;5;28mself\u001b[39m\u001b[38;5;241m.\u001b[39mdisconnect()\n\u001b[0;32m-> 1360\u001b[0m \u001b[38;5;28mself\u001b[39m\u001b[38;5;241m.\u001b[39m_open_connection()\n\u001b[1;32m   1362\u001b[0m charset, collation \u001b[38;5;241m=\u001b[39m (\n\u001b[1;32m   1363\u001b[0m     kwargs\u001b[38;5;241m.\u001b[39mpop(\u001b[38;5;124m\"\u001b[39m\u001b[38;5;124mcharset\u001b[39m\u001b[38;5;124m\"\u001b[39m, \u001b[38;5;28;01mNone\u001b[39;00m),\n\u001b[1;32m   1364\u001b[0m     kwargs\u001b[38;5;241m.\u001b[39mpop(\u001b[38;5;124m\"\u001b[39m\u001b[38;5;124mcollation\u001b[39m\u001b[38;5;124m\"\u001b[39m, \u001b[38;5;28;01mNone\u001b[39;00m),\n\u001b[1;32m   1365\u001b[0m )\n\u001b[1;32m   1366\u001b[0m \u001b[38;5;28;01mif\u001b[39;00m charset \u001b[38;5;129;01mor\u001b[39;00m collation:\n",
      "File \u001b[0;32m~/miniconda3/envs/jupyter-env/lib/python3.11/site-packages/mysql/connector/connection.py:359\u001b[0m, in \u001b[0;36mMySQLConnection._open_connection\u001b[0;34m(self)\u001b[0m\n\u001b[1;32m    357\u001b[0m \u001b[38;5;28mself\u001b[39m\u001b[38;5;241m.\u001b[39m_socket \u001b[38;5;241m=\u001b[39m \u001b[38;5;28mself\u001b[39m\u001b[38;5;241m.\u001b[39m_get_connection()\n\u001b[1;32m    358\u001b[0m \u001b[38;5;28;01mtry\u001b[39;00m:\n\u001b[0;32m--> 359\u001b[0m     \u001b[38;5;28mself\u001b[39m\u001b[38;5;241m.\u001b[39m_socket\u001b[38;5;241m.\u001b[39mopen_connection()\n\u001b[1;32m    361\u001b[0m     \u001b[38;5;66;03m# do initial handshake\u001b[39;00m\n\u001b[1;32m    362\u001b[0m     \u001b[38;5;28mself\u001b[39m\u001b[38;5;241m.\u001b[39m_do_handshake()\n",
      "File \u001b[0;32m~/miniconda3/envs/jupyter-env/lib/python3.11/site-packages/mysql/connector/network.py:760\u001b[0m, in \u001b[0;36mMySQLTCPSocket.open_connection\u001b[0;34m(self)\u001b[0m\n\u001b[1;32m    758\u001b[0m     \u001b[38;5;28mself\u001b[39m\u001b[38;5;241m.\u001b[39msock\u001b[38;5;241m.\u001b[39mconnect(sockaddr)\n\u001b[1;32m    759\u001b[0m \u001b[38;5;28;01mexcept\u001b[39;00m \u001b[38;5;167;01mIOError\u001b[39;00m \u001b[38;5;28;01mas\u001b[39;00m err:\n\u001b[0;32m--> 760\u001b[0m     \u001b[38;5;28;01mraise\u001b[39;00m InterfaceError(\n\u001b[1;32m    761\u001b[0m         errno\u001b[38;5;241m=\u001b[39m\u001b[38;5;241m2003\u001b[39m,\n\u001b[1;32m    762\u001b[0m         values\u001b[38;5;241m=\u001b[39m(\n\u001b[1;32m    763\u001b[0m             \u001b[38;5;28mself\u001b[39m\u001b[38;5;241m.\u001b[39mserver_host,\n\u001b[1;32m    764\u001b[0m             \u001b[38;5;28mself\u001b[39m\u001b[38;5;241m.\u001b[39mserver_port,\n\u001b[1;32m    765\u001b[0m             _strioerror(err),\n\u001b[1;32m    766\u001b[0m         ),\n\u001b[1;32m    767\u001b[0m     ) \u001b[38;5;28;01mfrom\u001b[39;00m \u001b[38;5;21;01merr\u001b[39;00m\n\u001b[1;32m    768\u001b[0m \u001b[38;5;28;01mexcept\u001b[39;00m \u001b[38;5;167;01mException\u001b[39;00m \u001b[38;5;28;01mas\u001b[39;00m err:\n\u001b[1;32m    769\u001b[0m     \u001b[38;5;28;01mraise\u001b[39;00m OperationalError(\u001b[38;5;28mstr\u001b[39m(err)) \u001b[38;5;28;01mfrom\u001b[39;00m \u001b[38;5;21;01merr\u001b[39;00m\n",
      "\u001b[0;31mInterfaceError\u001b[0m: 2003: Can't connect to MySQL server on 'localhost:3306' (61 Connection refused)"
     ]
    }
   ],
   "source": [
    "\n",
    "mydb = mysql.connector.connect(\n",
    "    host=\"localhost\",\n",
    "    user=\"yourusername\",\n",
    "    password=\"yourpassword\",\n",
    "    database=\"your_database\"\n",
    ")\n",
    "\n",
    "\n",
    "cursor = mydb.cursor()\n",
    "\n"
   ]
  },
  {
   "cell_type": "code",
   "execution_count": null,
   "id": "3839a527",
   "metadata": {},
   "outputs": [],
   "source": []
  }
 ],
 "metadata": {
  "kernelspec": {
   "display_name": "Python 3 (ipykernel)",
   "language": "python",
   "name": "python3"
  },
  "language_info": {
   "codemirror_mode": {
    "name": "ipython",
    "version": 3
   },
   "file_extension": ".py",
   "mimetype": "text/x-python",
   "name": "python",
   "nbconvert_exporter": "python",
   "pygments_lexer": "ipython3",
   "version": "3.11.5"
  }
 },
 "nbformat": 4,
 "nbformat_minor": 5
}
